Workbook
Name Slicer_Representative: #N/A

Sheet Sheet3
A4: Count of Call number | B4: Sum of Duration | C4: Sum of Purchase Amount | D4: Average of 5* Calls | E4: Average of Satisfaction Rating
A5: 1000 | B5: 89850 | C5: 96623 | D5: 307 | E5: 3.8854
A14: Count of Call number | B14: Sum of Duration | C14: Sum of Purchase Amount | D14: Average of 5* Calls | E14: Average of Satisfaction Rating
A15: 200 | B15: 18209 | C15: 20104 | D15: 307 | E15: 3.8825
A29: Date of Call2 | B29: Count of Call number | C29: Count of Call number2
A30: January | B30: 6 | C30: 6
A31: February | B31: 7 | C31: 7
A32: March | B32: 24 | C32: 24
A33: April | B33: 12 | C33: 12
A34: May | B34: 5 | C34: 5
A35: June | B35: 6 | C35: 6
A36: July | B36: 3 | C36: 3
A37: August | B37: 2 | C37: 2
A38: September | B38: 8 | C38: 8
A39: October | B39: 14 | C39: 14
A40: November | B40: 7 | C40: 7
A41: December | B41: 3 | C41: 3
A42: Grand Total | B42: 97 | C42: 97
A55: Day of week | B55: Count of Call number
A56: Sunday | B56: 27
A57: Monday | B57: 22
A58: Tuesday | B58: 27
A59: Wednesday | B59: 27
A60: Thursday | B60: 27
A61: Friday | B61: 32
A62: Saturday | B62: 38
A63: Grand Total | B63: 200
E75: For graph | G75: Selected rep | H75: =A90 -> R05
E76: Rep | F76: Call | G76: Amount | H76: Sel.calls | I76: Sel.amount
A77: Representative | B77: Count of Call number | C77: Sum of Purchase Amount | E77: {=A78:C82} -> R01 | F77: 189 | G77: 18415 | H77: =IF(E77=$H$75,F77,NA()) -> #N/A | I77: =IF(E77=$H$75,G77,NA()) -> #N/A
A78: R01 | B78: 189 | C78: 18415 | E78: R02 | F78: 218 | G78: 20581 | H78: =IF(E78=$H$75,F78,NA()) -> #N/A | I78: =IF(E78=$H$75,G78,NA()) -> #N/A
A79: R02 | B79: 218 | C79: 20581 | E79: R03 | F79: 207 | G79: 20872 | H79: =IF(E79=$H$75,F79,NA()) -> #N/A | I79: =IF(E79=$H$75,G79,NA()) -> #N/A
A80: R03 | B80: 207 | C80: 20872 | E80: R04 | F80: 186 | G80: 16651 | H80: =IF(E80=$H$75,F80,NA()) -> #N/A | I80: =IF(E80=$H$75,G80,NA()) -> #N/A
A81: R04 | B81: 186 | C81: 16651 | E81: R05 | F81: 200 | G81: 20104 | H81: =IF(E81=$H$75,F81,NA()) -> 200 | I81: =IF(E81=$H$75,G81,NA()) -> 20104
A82: R05 | B82: 200 | C82: 20104
A83: Grand Total | B83: 1000 | C83: 96623
A89: Representative
A90: R05
C94: Count of Call number | D94: Gender
C95: City | D95: Female | E95: Male | F95: Grand Total
...

Sheet Data
B1: Call Centre Data
B3: Call number | C3: Customer ID | D3: Gender | E3: Age | F3: City | G3: Duration | H3: Representative | I3: Date of Call | J3: Purchase Amount | K3: Satisfaction Rating | L3: FY | M3: Day of week | N3: Duration Bucket | O3: Rating rounded | P3: 5* Calls | U3: Customer ID | V3: Gender | W3: Age | X3: City
B4: Call_7271 | C4: C0003 | D4: {=_xlfn.XLOOKUP(C4,customers[Customer ID],customers[Gender],"")} -> Male | E4: {=_xlfn.XLOOKUP(C4,customers[Customer ID],customers[Age],"")} -> 26 | F4: {=_xlfn.XLOOKUP(C4,customers[Customer ID],customers[City],"")} -> Cincinnati | G4: 116 | H4: R05 | I4: 44927 | J4: 128 | K4: 4.9 | L4: =IF(MONTH(calls[[#This Row],[Date of Call]])<=6,YEAR(calls[[#This Row],[Date of Call]]),YEAR(calls[[#This Row],[Date of Call]])+1) -> 2023 | M4: =TEXT(calls[[#This Row],[Date of Call]],"DDDD") -> Sunday | N4: {=_xlfn.IFS(calls[[#This Row],[Duration]]<=10,"Under 10 mins",calls[[#This Row],[Duration]]<=30,"10 to 30 mins",calls[[#This Row],[Duration]]<=60,"30 to 60 mins",calls[[#This Row],[Duration]]<=120,"1 to 2 hours",TRUE,"More than 2 hours")} -> 1 to 2 hours | O4: =ROUND(calls[[#This Row],[Satisfaction Rating]],0) -> 5 | P4: =COUNTIF(O:O,5) -> 307 | U4: C0001 | V4: Male | W4: 41 | X4: Columbus
B5: Call_7272 | C5: C0004 | D5: {=_xlfn.XLOOKUP(C5,customers[Customer ID],customers[Gender],"")} -> Male | E5: {=_xlfn.XLOOKUP(C5,customers[Customer ID],customers[Age],"")} -> 36 | F5: {=_xlfn.XLOOKUP(C5,customers[Customer ID],customers[City],"")} -> Cincinnati | G5: 119 | H5: R05 | I5: 44927 | J5: 135 | K5: 2.9 | L5: =IF(MONTH(calls[[#This Row],[Date of Call]])<=6,YEAR(calls[[#This Row],[Date of Call]]),YEAR(calls[[#This Row],[Date of Call]])+1) -> 2023 | M5: =TEXT(calls[[#This Row],[Date of Call]],"DDDD") -> Sunday | N5: {=_xlfn.IFS(calls[[#This Row],[Duration]]<=10,"Under 10 mins",calls[[#This Row],[Duration]]<=30,"10 to 30 mins",calls[[#This Row],[Duration]]<=60,"30 to 60 mins",calls[[#This Row],[Duration]]<=120,"1 to 2 hours",TRUE,"More than 2 hours")} -> 1 to 2 hours | O5: =ROUND(calls[[#This Row],[Satisfaction Rating]],0) -> 3 | P5: =COUNTIF(O:O,5) -> 307 | U5: C0002 | V5: Male | W5: 31 | X5: Cleveland
B6: Call_7273 | C6: C0005 | D6: {=_xlfn.XLOOKUP(C6,customers[Customer ID],customers[Gender],"")} -> Male | E6: {=_xlfn.XLOOKUP(C6,customers[Customer ID],customers[Age],"")} -> 37 | F6: {=_xlfn.XLOOKUP(C6,customers[Customer ID],customers[City],"")} -> Columbus | G6: 68 | H6: R02 | I6: 44927 | J6: 66 | K6: 4.7 | L6: =IF(MONTH(calls[[#This Row],[Date of Call]])<=6,YEAR(calls[[#This Row],[Date of Call]]),YEAR(calls[[#This Row],[Date of Call]])+1) -> 2023 | M6: =TEXT(calls[[#This Row],[Date of Call]],"DDDD") -> Sunday | N6: {=_xlfn.IFS(calls[[#This Row],[Duration]]<=10,"Under 10 mins",calls[[#This Row],[Duration]]<=30,"10 to 30 mins",calls[[#This Row],[Duration]]<=60,"30 to 60 mins",calls[[#This Row],[Duration]]<=120,"1 to 2 hours",TRUE,"More than 2 hours")} -> 1 to 2 hours | O6: =ROUND(calls[[#This Row],[Satisfaction Rating]],0) -> 5 | P6: =COUNTIF(O:O,5) -> 307 | U6: C0003 | V6: Male | W6: 26 | X6: Cincinnati
B7: Call_7274 | C7: C0014 | D7: {=_xlfn.XLOOKUP(C7,customers[Customer ID],customers[Gender],"")} -> Female | E7: {=_xlfn.XLOOKUP(C7,customers[Customer ID],customers[Age],"")} -> 38 | F7: {=_xlfn.XLOOKUP(C7,customers[Customer ID],customers[City],"")} -> Columbus | G7: 119 | H7: R02 | I7: 44927 | J7: 22 | K7: 2.9 | L7: =IF(MONTH(calls[[#This Row],[Date of Call]])<=6,YEAR(calls[[#This Row],[Date of Call]]),YEAR(calls[[#This Row],[Date of Call]])+1) -> 2023 | M7: =TEXT(calls[[#This Row],[Date of Call]],"DDDD") -> Sunday | N7: {=_xlfn.IFS(calls[[#This Row],[Duration]]<=10,"Under 10 mins",calls[[#This Row],[Duration]]<=30,"10 to 30 mins",calls[[#This Row],[Duration]]<=60,"30 to 60 mins",calls[[#This Row],[Duration]]<=120,"1 to 2 hours",TRUE,"More than 2 hours")} -> 1 to 2 hours | O7: =ROUND(calls[[#This Row],[Satisfaction Rating]],0) -> 3 | P7: =COUNTIF(O:O,5) -> 307 | U7: C0004 | V7: Male | W7: 36 | X7: Cincinnati
B8: Call_7275 | C8: C0011 | D8: {=_xlfn.XLOOKUP(C8,customers[Customer ID],customers[Gender],"")} -> Female | E8: {=_xlfn.XLOOKUP(C8,customers[Customer ID],customers[Age],"")} -> 30 | F8: {=_xlfn.XLOOKUP(C8,customers[Customer ID],customers[City],"")} -> Cincinnati | G8: 128 | H8: R01 | I8: 44928 | J8: 31 | K8: 2.8 | L8: =IF(MONTH(calls[[#This Row],[Date of Call]])<=6,YEAR(calls[[#This Row],[Date of Call]]),YEAR(calls[[#This Row],[Date of Call]])+1) -> 2023 | M8: =TEXT(calls[[#This Row],[Date of Call]],"DDDD") -> Monday | N8: {=_xlfn.IFS(calls[[#This Row],[Duration]]<=10,"Under 10 mins",calls[[#This Row],[Duration]]<=30,"10 to 30 mins",calls[[#This Row],[Duration]]<=60,"30 to 60 mins",calls[[#This Row],[Duration]]<=120,"1 to 2 hours",TRUE,"More than 2 hours")} -> More than 2 hours | O8: =ROUND(calls[[#This Row],[Satisfaction Rating]],0) -> 3 | P8: =COUNTIF(O:O,5) -> 307 | U8: C0005 | V8: Male | W8: 37 | X8: Columbus
B9: Call_7276 | C9: C0011 | D9: {=_xlfn.XLOOKUP(C9,customers[Customer ID],customers[Gender],"")} -> Female | E9: {=_xlfn.XLOOKUP(C9,customers[Customer ID],customers[Age],"")} -> 30 | F9: {=_xlfn.XLOOKUP(C9,customers[Customer ID],customers[City],"")} -> Cincinnati | G9: 49 | H9: R02 | I9: 44929 | J9: 135 | K9: 4.8 | L9: =IF(MONTH(calls[[#This Row],[Date of Call]])<=6,YEAR(calls[[#This Row],[Date of Call]]),YEAR(calls[[#This Row],[Date of Call]])+1) -> 2023 | M9: =TEXT(calls[[#This Row],[Date of Call]],"DDDD") -> Tuesday | N9: {=_xlfn.IFS(calls[[#This Row],[Duration]]<=10,"Under 10 mins",calls[[#This Row],[Duration]]<=30,"10 to 30 mins",calls[[#This Row],[Duration]]<=60,"30 to 60 mins",calls[[#This Row],[Duration]]<=120,"1 to 2 hours",TRUE,"More than 2 hours")} -> 30 to 60 mins | O9: =ROUND(calls[[#This Row],[Satisfaction Rating]],0) -> 5 | P9: =COUNTIF(O:O,5) -> 307 | U9: C0006 | V9: Male | W9: 23 | X9: Columbus
B10: Call_7277 | C10: C0007 | D10: {=_xlfn.XLOOKUP(C10,customers[Customer ID],customers[Gender],"")} -> Female | E10: {=_xlfn.XLOOKUP(C10,customers[Customer ID],customers[Age],"")} -> 22 | F10: {=_xlfn.XLOOKUP(C10,customers[Customer ID],customers[City],"")} -> Cleveland | G10: 84 | H10: R05 | I10: 44929 | J10: 60 | K10: 4.7 | L10: =IF(MONTH(calls[[#This Row],[Date of Call]])<=6,YEAR(calls[[#This Row],[Date of Call]]),YEAR(calls[[#This Row],[Date of Call]])+1) -> 2023 | M10: =TEXT(calls[[#This Row],[Date of Call]],"DDDD") -> Tuesday | N10: {=_xlfn.IFS(calls[[#This Row],[Duration]]<=10,"Under 10 mins",calls[[#This Row],[Duration]]<=30,"10 to 30 mins",calls[[#This Row],[Duration]]<=60,"30 to 60 mins",calls[[#This Row],[Duration]]<=120,"1 to 2 hours",TRUE,"More than 2 hours")} -> 1 to 2 hours | O10: =ROUND(calls[[#This Row],[Satisfaction Rating]],0) -> 5 | P10: =COUNTIF(O:O,5) -> 307 | U10: C0007 | V10: Female | W10: 22 | X10: Cleveland
B11: Call_7278 | C11: C0003 | D11: {=_xlfn.XLOOKUP(C11,customers[Customer ID],customers[Gender],"")} -> Male | E11: {=_xlfn.XLOOKUP(C11,customers[Customer ID],customers[Age],"")} -> 26 | F11: {=_xlfn.XLOOKUP(C11,customers[Customer ID],customers[City],"")} -> Cincinnati | G11: 103 | H11: R04 | I11: 44929 | J11: 148 | K11: 4.4 | L11: =IF(MONTH(calls[[#This Row],[Date of Call]])<=6,YEAR(calls[[#This Row],[Date of Call]]),YEAR(calls[[#This Row],[Date of Call]])+1) -> 2023 | M11: =TEXT(calls[[#This Row],[Date of Call]],"DDDD") -> Tuesday | N11: {=_xlfn.IFS(calls[[#This Row],[Duration]]<=10,"Under 10 mins",calls[[#This Row],[Duration]]<=30,"10 to 30 mins",calls[[#This Row],[Duration]]<=60,"30 to 60 mins",calls[[#This Row],[Duration]]<=120,"1 to 2 hours",TRUE,"More than 2 hours")} -> 1 to 2 hours | O11: =ROUND(calls[[#This Row],[Satisfaction Rating]],0) -> 4 | P11: =COUNTIF(O:O,5) -> 307 | U11: C0008 | V11: Female | W11: 42 | X11: Cleveland
B12: Call_7279 | C12: C0005 | D12: {=_xlfn.XLOOKUP(C12,customers[Customer ID],customers[Gender],"")} -> Male | E12: {=_xlfn.XLOOKUP(C12,customers[Customer ID],customers[Age],"")} -> 37 | F12: {=_xlfn.XLOOKUP(C12,customers[Customer ID],customers[City],"")} -> Columbus | G12: 31 | H12: R02 | I12: 44929 | J12: 135 | K12: 3.6 | L12: =IF(MONTH(calls[[#This Row],[Date of Call]])<=6,YEAR(calls[[#This Row],[Date of Call]]),YEAR(calls[[#This Row],[Date of Call]])+1) -> 2023 | M12: =TEXT(calls[[#This Row],[Date of Call]],"DDDD") -> Tuesday | N12: {=_xlfn.IFS(calls[[#This Row],[Duration]]<=10,"Under 10 mins",calls[[#This Row],[Duration]]<=30,"10 to 30 mins",calls[[#This Row],[Duration]]<=60,"30 to 60 mins",calls[[#This Row],[Duration]]<=120,"1 to 2 hours",TRUE,"More than 2 hours")} -> 30 to 60 mins | O12: =ROUND(calls[[#This Row],[Satisfaction Rating]],0) -> 4 | P12: =COUNTIF(O:O,5) -> 307 | U12: C0009 | V12: Female | W12: 25 | X12: Columbus
B13: Call_7280 | C13: C0010 | D13: {=_xlfn.XLOOKUP(C13,customers[Customer ID],customers[Gender],"")} -> Female | E13: {=_xlfn.XLOOKUP(C13,customers[Customer ID],customers[Age],"")} -> 30 | F13: {=_xlfn.XLOOKUP(C13,customers[Customer ID],customers[City],"")} -> Cleveland | G13: 44 | H13: R03 | I13: 44929 | J13: 105 | K13: 2.9 | L13: =IF(MONTH(calls[[#This Row],[Date of Call]])<=6,YEAR(calls[[#This Row],[Date of Call]]),YEAR(calls[[#This Row],[Date of Call]])+1) -> 2023 | M13: =TEXT(calls[[#This Row],[Date of Call]],"DDDD") -> Tuesday | N13: {=_xlfn.IFS(calls[[#This Row],[Duration]]<=10,"Under 10 mins",calls[[#This Row],[Duration]]<=30,"10 to 30 mins",calls[[#This Row],[Duration]]<=60,"30 to 60 mins",calls[[#This Row],[Duration]]<=120,"1 to 2 hours",TRUE,"More than 2 hours")} -> 30 to 60 mins | O13: =ROUND(calls[[#This Row],[Satisfaction Rating]],0) -> 3 | P13: =COUNTIF(O:O,5) -> 307 | U13: C0010 | V13: Female | W13: 30 | X13: Cleveland
B14: Call_7281 | C14: C0011 | D14: {=_xlfn.XLOOKUP(C14,customers[Customer ID],customers[Gender],"")} -> Female | E14: {=_xlfn.XLOOKUP(C14,customers[Customer ID],customers[Age],"")} -> 30 | F14: {=_xlfn.XLOOKUP(C14,customers[Customer ID],customers[City],"")} -> Cincinnati | G14: 102 | H14: R02 | I14: 44929 | J14: 69 | K14: 4.9 | L14: =IF(MONTH(calls[[#This Row],[Date of Call]])<=6,YEAR(calls[[#This Row],[Date of Call]]),YEAR(calls[[#This Row],[Date of Call]])+1) -> 2023 | M14: =TEXT(calls[[#This Row],[Date of Call]],"DDDD") -> Tuesday | N14: {=_xlfn.IFS(calls[[#This Row],[Duration]]<=10,"Under 10 mins",calls[[#This Row],[Duration]]<=30,"10 to 30 mins",calls[[#This Row],[Duration]]<=60,"30 to 60 mins",calls[[#This Row],[Duration]]<=120,"1 to 2 hours",TRUE,"More than 2 hours")} -> 1 to 2 hours | O14: =ROUND(calls[[#This Row],[Satisfaction Rating]],0) -> 5 | P14: =COUNTIF(O:O,5) -> 307 | U14: C0011 | V14: Female | W14: 30 | X14: Cincinnati
B15: Call_7282 | C15: C0013 | D15: {=_xlfn.XLOOKUP(C15,customers[Customer ID],customers[Gender],"")} -> Female | E15: {=_xlfn.XLOOKUP(C15,customers[Customer ID],customers[Age],"")} -> 37 | F15: {=_xlfn.XLOOKUP(C15,customers[Customer ID],customers[City],"")} -> Cleveland | G15: 135 | H15: R05 | I15: 44929 | J15: 46 | K15: 3.4 | L15: =IF(MONTH(calls[[#This Row],[Date of Call]])<=6,YEAR(calls[[#This Row],[Date of Call]]),YEAR(calls[[#This Row],[Date of Call]])+1) -> 2023 | M15: =TEXT(calls[[#This Row],[Date of Call]],"DDDD") -> Tuesday | N15: {=_xlfn.IFS(calls[[#This Row],[Duration]]<=10,"Under 10 mins",calls[[#This Row],[Duration]]<=30,"10 to 30 mins",calls[[#This Row],[Duration]]<=60,"30 to 60 mins",calls[[#This Row],[Duration]]<=120,"1 to 2 hours",TRUE,"More than 2 hours")} -> More than 2 hours | O15: =ROUND(calls[[#This Row],[Satisfaction Rating]],0) -> 3 | P15: =COUNTIF(O:O,5) -> 307 | U15: C0012 | V15: Female | W15: 28 | X15: Cincinnati
... B18: Call_7285 | C18: C0013 | D18: {=_xlfn.XLOOKUP(C18,customers[Customer ID],customers[Gender],"")} -> Female | E18: {=_xlfn.XLOOKUP(C18,customers[Customer ID],customers[Age],"")} -> 37 | F18: {=_xlfn.XLOOKUP(C18,customers[Customer ID],customers[City],"")} -> Cleveland | G18: 48 | H18: R01 | I18: 44930 | J18: 68 | K18: 4.9 | L18: =IF(MONTH(calls[[#This Row],[Date of Call]])<=6,YEAR(calls[[#This Row],[Date of Call]]),YEAR(calls[[#This Row],[Date of Call]])+1) -> 2023 | M18: =TEXT(calls[[#This Row],[Date of Call]],"DDDD") -> Wednesday | N18: {=_xlfn.IFS(calls[[#This Row],[Duration]]<=10,"Under 10 mins",calls[[#This Row],[Duration]]<=30,"10 to 30 mins",calls[[#This Row],[Duration]]<=60,"30 to 60 mins",calls[[#This Row],[Duration]]<=120,"1 to 2 hours",TRUE,"More than 2 hours")} -> 30 to 60 mins | O18: =ROUND(calls[[#This Row],[Satisfaction Rating]],0) -> 5 | P18: =COUNTIF(O:O,5) -> 307 | U18: C0015 | V18: Female | W18: 43 | X18: Cleveland
B19: Call_7286 | C19: C0010 | D19: {=_xlfn.XLOOKUP(C19,customers[Customer ID],customers[Gender],"")} -> Female | E19: {=_xlfn.XLOOKUP(C19,customers[Customer ID],customers[Age],"")} -> 30 | F19: {=_xlfn.XLOOKUP(C19,customers[Customer ID],customers[City],"")} -> Cleveland | G19: 176 | H19: R05 | I19: 44931 | J19: 24 | K19: 4.8 | L19: =IF(MONTH(calls[[#This Row],[Date of Call]])<=6,YEAR(calls[[#This Row],[Date of Call]]),YEAR(calls[[#This Row],[Date of Call]])+1) -> 2023 | M19: =TEXT(calls[[#This Row],[Date of Call]],"DDDD") -> Thursday | N19: {=_xlfn.IFS(calls[[#This Row],[Duration]]<=10,"Under 10 mins",calls[[#This Row],[Duration]]<=30,"10 to 30 mins",calls[[#This Row],[Duration]]<=60,"30 to 60 mins",calls[[#This Row],[Duration]]<=120,"1 to 2 hours",TRUE,"More than 2 hours")} -> More than 2 hours | O19: =ROUND(calls[[#This Row],[Satisfaction Rating]],0) -> 5 | P19: =COUNTIF(O:O,5) -> 307
B20: Call_7287 | C20: C0010 | D20: {=_xlfn.XLOOKUP(C20,customers[Customer ID],customers[Gender],"")} -> Female | E20: {=_xlfn.XLOOKUP(C20,customers[Customer ID],customers[Age],"")} -> 30 | F20: {=_xlfn.XLOOKUP(C20,customers[Customer ID],customers[City],"")} -> Cleveland | G20: 99 | H20: R01 | I20: 44931 | J20: 195 | K20: 3.9 | L20: =IF(MONTH(calls[[#This Row],[Date of Call]])<=6,YEAR(calls[[#This Row],[Date of Call]]),YEAR(calls[[#This Row],[Date of Call]])+1) -> 2023 | M20: =TEXT(calls[[#This Row],[Date of Call]],"DDDD") -> Thursday | N20: {=_xlfn.IFS(calls[[#This Row],[Duration]]<=10,"Under 10 mins",calls[[#This Row],[Duration]]<=30,"10 to 30 mins",calls[[#This Row],[Duration]]<=60,"30 to 60 mins",calls[[#This Row],[Duration]]<=120,"1 to 2 hours",TRUE,"More than 2 hours")} -> 1 to 2 hours | O20: =ROUND(calls[[#This Row],[Satisfaction Rating]],0) -> 4 | P20: =COUNTIF(O:O,5) -> 307
B21: Call_7288 | C21: C0009 | D21: {=_xlfn.XLOOKUP(C21,customers[Customer ID],customers[Gender],"")} -> Female | E21: {=_xlfn.XLOOKUP(C21,customers[Customer ID],customers[Age],"")} -> 25 | F21: {=_xlfn.XLOOKUP(C21,customers[Customer ID],customers[City],"")} -> Columbus | G21: 28 | H21: R03 | I21: 44931 | J21: 28 | K21: 3.8 | L21: =IF(MONTH(calls[[#This Row],[Date of Call]])<=6,YEAR(calls[[#This Row],[Date of Call]]),YEAR(calls[[#This Row],[Date of Call]])+1) -> 2023 | M21: =TEXT(calls[[#This Row],[Date of Call]],"DDDD") -> Thursday | N21: {=_xlfn.IFS(calls[[#This Row],[Duration]]<=10,"Under 10 mins",calls[[#This Row],[Duration]]<=30,"10 to 30 mins",calls[[#This Row],[Duration]]<=60,"30 to 60 mins",calls[[#This Row],[Duration]]<=120,"1 to 2 hours",TRUE,"More than 2 hours")} -> 10 to 30 mins | O21: =ROUND(calls[[#This Row],[Satisfaction Rating]],0) -> 4 | P21: =COUNTIF(O:O,5) -> 307
B22: Call_7289 | C22: C0007 | D22: {=_xlfn.XLOOKUP(C22,customers[Customer ID],customers[Gender],"")} -> Female | E22: {=_xlfn.XLOOKUP(C22,customers[Customer ID],customers[Age],"")} -> 22 | F22: {=_xlfn.XLOOKUP(C22,customers[Customer ID],customers[City],"")} -> Cleveland | G22: 54 | H22: R02 | I22: 44931 | J22: 170 | K22: 4.3 | L22: =IF(MONTH(calls[[#This Row],[Date of Call]])<=6,YEAR(calls[[#This Row],[Date of Call]]),YEAR(calls[[#This Row],[Date of Call]])+1) -> 2023 | M22: =TEXT(calls[[#This Row],[Date of Call]],"DDDD") -> Thursday | N22: {=_xlfn.IFS(calls[[#This Row],[Duration]]<=10,"Under 10 mins",calls[[#This Row],[Duration]]<=30,"10 to 30 mins",calls[[#This Row],[Duration]]<=60,"30 to 60 mins",calls[[#This Row],[Duration]]<=120,"1 to 2 hours",TRUE,"More than 2 hours")} -> 30 to 60 mins | O22: =ROUND(calls[[#This Row],[Satisfaction Rating]],0) -> 4 | P22: =COUNTIF(O:O,5) -> 307
B23: Call_7290 | C23: C0006 | D23: {=_xlfn.XLOOKUP(C23,customers[Customer ID],customers[Gender],"")} -> Male | E23: {=_xlfn.XLOOKUP(C23,customers[Customer ID],customers[Age],"")} -> 23 | F23: {=_xlfn.XLOOKUP(C23,customers[Customer ID],customers[City],"")} -> Columbus | G23: 48 | H23: R05 | I23: 44932 | J23: 30 | K23: 4.4 | L23: =IF(MONTH(calls[[#This Row],[Date of Call]])<=6,YEAR(calls[[#This Row],[Date of Call]]),YEAR(calls[[#This Row],[Date of Call]])+1) -> 2023 | M23: =TEXT(calls[[#This Row],[Date of Call]],"DDDD") -> Friday | N23: {=_xlfn.IFS(calls[[#This Row],[Duration]]<=10,"Under 10 mins",calls[[#This Row],[Duration]]<=30,"10 to 30 mins",calls[[#This Row],[Duration]]<=60,"30 to 60 mins",calls[[#This Row],[Duration]]<=120,"1 to 2 hours",TRUE,"More than 2 hours")} -> 30 to 60 mins | O23: =ROUND(calls[[#This Row],[Satisfaction Rating]],0) -> 4 | P23: =COUNTIF(O:O,5) -> 307
B24: Call_7291 | C24: C0004 | D24: {=_xlfn.XLOOKUP(C24,customers[Customer ID],customers[Gender],"")} -> Male | E24: {=_xlfn.XLOOKUP(C24,customers[Customer ID],customers[Age],"")} -> 36 | F24: {=_xlfn.XLOOKUP(C24,customers[Customer ID],customers[City],"")} -> Cincinnati | G24: 128 | H24: R05 | I24: 44932 | J24: 72 | K24: 5 | L24: =IF(MONTH(calls[[#This Row],[Date of Call]])<=6,YEAR(calls[[#This Row],[Date of Call]]),YEAR(calls[[#This Row],[Date of Call]])+1) -> 2023 | M24: =TEXT(calls[[#This Row],[Date of Call]],"DDDD") -> Friday | N24: {=_xlfn.IFS(calls[[#This Row],[Duration]]<=10,"Under 10 mins",calls[[#This Row],[Duration]]<=30,"10 to 30 mins",calls[[#This Row],[Duration]]<=60,"30 to 60 mins",calls[[#This Row],[Duration]]<=120,"1 to 2 hours",TRUE,"More than 2 hours")} -> More than 2 hours | O24: =ROUND(calls[[#This Row],[Satisfaction Rating]],0) -> 5 | P24: =COUNTIF(O:O,5) -> 307
B25: Call_7292 | C25: C0004 | D25: {=_xlfn.XLOOKUP(C25,customers[Customer ID],customers[Gender],"")} -> Male | E25: {=_xlfn.XLOOKUP(C25,customers[Customer ID],customers[Age],"")} -> 36 | F25: {=_xlfn.XLOOKUP(C25,customers[Customer ID],customers[City],"")} -> Cincinnati | G25: 38 | H25: R04 | I25: 44933 | J25: 92 | K25: 4.9 | L25: =IF(MONTH(calls[[#This Row],[Date of Call]])<=6,YEAR(calls[[#This Row],[Date of Call]]),YEAR(calls[[#This Row],[Date of Call]])+1) -> 2023 | M25: =TEXT(calls[[#This Row],[Date of Call]],"DDDD") -> Saturday | N25: {=_xlfn.IFS(calls[[#This Row],[Duration]]<=10,"Under 10 mins",calls[[#This Row],[Duration]]<=30,"10 to 30 mins",calls[[#This Row],[Duration]]<=60,"30 to 60 mins",calls[[#This Row],[Duration]]<=120,"1 to 2 hours",TRUE,"More than 2 hours")} -> 30 to 60 mins | O25: =ROUND(calls[[#This Row],[Satisfaction Rating]],0) -> 5 | P25: =COUNTIF(O:O,5) -> 307
B26: Call_7293 | C26: C0003 | D26: {=_xlfn.XLOOKUP(C26,customers[Customer ID],customers[Gender],"")} -> Male | E26: {=_xlfn.XLOOKUP(C26,customers[Customer ID],customers[Age],"")} -> 26 | F26: {=_xlfn.XLOOKUP(C26,customers[Customer ID],customers[City],"")} -> Cincinnati | G26: 67 | H26: R04 | I26: 44934 | J26: 165 | K26: 4.5 | L26: =IF(MONTH(calls[[#This Row],[Date of Call]])<=6,YEAR(calls[[#This Row],[Date of Call]]),YEAR(calls[[#This Row],[Date of Call]])+1) -> 2023 | M26: =TEXT(calls[[#This Row],[Date of Call]],"DDDD") -> Sunday | N26: {=_xlfn.IFS(calls[[#This Row],[Duration]]<=10,"Under 10 mins",calls[[#This Row],[Duration]]<=30,"10 to 30 mins",calls[[#This Row],[Duration]]<=60,"30 to 60 mins",calls[[#This Row],[Duration]]<=120,"1 to 2 hours",TRUE,"More than 2 hours")} -> 1 to 2 hours | O26: =ROUND(calls[[#This Row],[Satisfaction Rating]],0) -> 5 | P26: =COUNTIF(O:O,5) -> 307
B27: Call_7294 | C27: C0015 | D27: {=_xlfn.XLOOKUP(C27,customers[Customer ID],customers[Gender],"")} -> Female | E27: {=_xlfn.XLOOKUP(C27,customers[Customer ID],customers[Age],"")} -> 43 | F27: {=_xlfn.XLOOKUP(C27,customers[Customer ID],customers[City],"")} -> Cleveland | G27: 58 | H27: R02 | I27: 44934 | J27: 140 | K27: 2.1 | L27: =IF(MONTH(calls[[#This Row],[Date of Call]])<=6,YEAR(calls[[#This Row],[Date of Call]]),YEAR(calls[[#This Row],[Date of Call]])+1) -> 2023 | M27: =TEXT(calls[[#This Row],[Date of Call]],"DDDD") -> Sunday | N27: {=_xlfn.IFS(calls[[#This Row],[Duration]]<=10,"Under 10 mins",calls[[#This Row],[Duration]]<=30,"10 to 30 mins",calls[[#This Row],[Duration]]<=60,"30 to 60 mins",calls[[#This Row],[Duration]]<=120,"1 to 2 hours",TRUE,"More than 2 hours")} -> 30 to 60 mins | O27: =ROUND(calls[[#This Row],[Satisfaction Rating]],0) -> 2 | P27: =COUNTIF(O:O,5) -> 307
B28: Call_7295 | C28: C0010 | D28: {=_xlfn.XLOOKUP(C28,customers[Customer ID],customers[Gender],"")} -> Female | E28: {=_xlfn.XLOOKUP(C28,customers[Customer ID],customers[Age],"")} -> 30 | F28: {=_xlfn.XLOOKUP(C28,customers[Customer ID],customers[City],"")} -> Cleveland | G28: 54 | H28: R01 | I28: 44934 | J28: 111 | K28: 3.3 | L28: =IF(MONTH(calls[[#This Row],[Date of Call]])<=6,YEAR(calls[[#This Row],[Date of Call]]),YEAR(calls[[#This Row],[Date of Call]])+1) -> 2023 | M28: =TEXT(calls[[#This Row],[Date of Call]],"DDDD") -> Sunday | N28: {=_xlfn.IFS(calls[[#This Row],[Duration]]<=10,"Under 10 mins",calls[[#This Row],[Duration]]<=30,"10 to 30 mins",calls[[#This Row],[Duration]]<=60,"30 to 60 mins",calls[[#This Row],[Duration]]<=120,"1 to 2 hours",TRUE,"More than 2 hours")} -> 30 to 60 mins | O28: =ROUND(calls[[#This Row],[Satisfaction Rating]],0) -> 3 | P28: =COUNTIF(O:O,5) -> 307
B29: Call_7296 | C29: C0012 | D29: {=_xlfn.XLOOKUP(C29,customers[Customer ID],customers[Gender],"")} -> Female | E29: {=_xlfn.XLOOKUP(C29,customers[Customer ID],customers[Age],"")} -> 28 | F29: {=_xlfn.XLOOKUP(C29,customers[Customer ID],customers[City],"")} -> Cincinnati | G29: 28 | H29: R05 | I29: 44935 | J29: 63 | K29: 4.1 | L29: =IF(MONTH(calls[[#This Row],[Date of Call]])<=6,YEAR(calls[[#This Row],[Date of Call]]),YEAR(calls[[#This Row],[Date of Call]])+1) -> 2023 | M29: =TEXT(calls[[#This Row],[Date of Call]],"DDDD") -> Monday | N29: {=_xlfn.IFS(calls[[#This Row],[Duration]]<=10,"Under 10 mins",calls[[#This Row],[Duration]]<=30,"10 to 30 mins",calls[[#This Row],[Duration]]<=60,"30 to 60 mins",calls[[#This Row],[Duration]]<=120,"1 to 2 hours",TRUE,"More than 2 hours")} -> 10 to 30 mins | O29: =ROUND(calls[[#This Row],[Satisfaction Rating]],0) -> 4 | P29: =COUNTIF(O:O,5) -> 307
B30: Call_7297 | C30: C0002 | D30: {=_xlfn.XLOOKUP(C30,customers[Customer ID],customers[Gender],"")} -> Male | E30: {=_xlfn.XLOOKUP(C30,customers[Customer ID],customers[Age],"")} -> 31 | F30: {=_xlfn.XLOOKUP(C30,customers[Customer ID],customers[City],"")} -> Cleveland | G30: 73 | H30: R05 | I30: 44935 | J30: 80 | K30: 4.2 | L30: =IF(MONTH(calls[[#This Row],[Date of Call]])<=6,YEAR(calls[[#This Row],[Date of Call]]),YEAR(calls[[#This Row],[Date of Call]])+1) -> 2023 | M30: =TEXT(calls[[#This Row],[Date of Call]],"DDDD") -> Monday | N30: {=_xlfn.IFS(calls[[#This Row],[Duration]]<=10,"Under 10 mins",calls[[#This Row],[Duration]]<=30,"10 to 30 mins",calls[[#This Row],[Duration]]<=60,"30 to 60 mins",calls[[#This Row],[Duration]]<=120,"1 to 2 hours",TRUE,"More than 2 hours")} -> 1 to 2 hours | O30: =ROUND(calls[[#This Row],[Satisfaction Rating]],0) -> 4 | P30: =COUNTIF(O:O,5) -> 307
... B1003: Call_8270 | C1003: C0009 | D1003: {=_xlfn.XLOOKUP(C1003,customers[Customer ID],customers[Gender],"")} -> Female | E1003: {=_xlfn.XLOOKUP(C1003,customers[Customer ID],customers[Age],"")} -> 25 | F1003: {=_xlfn.XLOOKUP(C1003,customers[Customer ID],customers[City],"")} -> Columbus | G1003: 114 | H1003: R01 | I1003: 45291 | J1003: 40 | K1003: 3.9 | L1003: =IF(MONTH(calls[[#This Row],[Date of Call]])<=6,YEAR(calls[[#This Row],[Date of Call]]),YEAR(calls[[#This Row],[Date of Call]])+1) -> 2024 | M1003: =TEXT(calls[[#This Row],[Date of Call]],"DDDD") -> Sunday | N1003: {=_xlfn.IFS(calls[[#This Row],[Duration]]<=10,"Under 10 mins",calls[[#This Row],[Duration]]<=30,"10 to 30 mins",calls[[#This Row],[Duration]]<=60,"30 to 60 mins",calls[[#This Row],[Duration]]<=120,"1 to 2 hours",TRUE,"More than 2 hours")} -> 1 to 2 hours | O1003: =ROUND(calls[[#This Row],[Satisfaction Rating]],0) -> 4 | P1003: =COUNTIF(O:O,5) -> 307

Sheet Assets
E2: Rep ID | F2: Rep Image
E3: R01
E4: R02 | F4: #VALUE!
E5: R03 | F5: #VALUE! | I5: Rep ID | J5: Rep Image
E6: R04 | F6: #VALUE! | I6: R01 | J6: =_xlfn.DISPIMG("ID_EC911822DCF444EC8A14DF6B7BA76BC9",1) -> =DISPIMG("ID_EC911822DCF444EC8A14DF6B7BA76BC9",1)
E7: R05 | F7: #VALUE! | I7: R02 | J7: =_xlfn.DISPIMG("ID_EC911822DCF444EC8A14DF6B7BA76BC9",1) -> =DISPIMG("ID_EC911822DCF444EC8A14DF6B7BA76BC9",1)
I8: R03 | J8: =_xlfn.DISPIMG("ID_EC911822DCF444EC8A14DF6B7BA76BC9",1) -> =DISPIMG("ID_EC911822DCF444EC8A14DF6B7BA76BC9",1)
I9: R04 | J9: =_xlfn.DISPIMG("ID_EC911822DCF444EC8A14DF6B7BA76BC9",1) -> =DISPIMG("ID_EC911822DCF444EC8A14DF6B7BA76BC9",1)
I10: R05 | J10: =_xlfn.DISPIMG("ID_EC911822DCF444EC8A14DF6B7BA76BC9",1) -> =DISPIMG("ID_EC911822DCF444EC8A14DF6B7BA76BC9",1)

Sheet Sheet2
A1: Call number | B1: Customer ID | C1: Gender | D1: Age | E1: City | F1: Duration | G1: Representative | H1: Date of Call | I1: Purchase Amount | J1: Satisfaction Rating | K1: FY | L1: Day of week | M1: Duration Bucket | N1: Rating rounded | O1: 5* Calls
A2: Call_7283 | B2: C0002 | C2: Male | D2: 31 | E2: Cleveland | F2: 98 | G2: R02 | H2: 44930 | I2: 108 | J2: 3.5 | K2: 2023 | L2: Wednesday | M2: 1 to 2 hours | N2: 4 | O2: 307
A3: Call_7284 | B3: C0010 | C3: Female | D3: 30 | E3: Cleveland | F3: 139 | G3: R02 | H3: 44930 | I3: 96 | J3: 4 | K3: 2023 | L3: Wednesday | M3: More than 2 hours | N3: 4 | O3: 307
A4: Call_7285 | B4: C0013 | C4: Female | D4: 37 | E4: Cleveland | F4: 48 | G4: R01 | H4: 44930 | I4: 68 | J4: 4.9 | K4: 2023 | L4: Wednesday | M4: 30 to 60 mins | N4: 5 | O4: 307
A5: Call_7312 | B5: C0010 | C5: Female | D5: 30 | E5: Cleveland | F5: 105 | G5: R02 | H5: 44944 | I5: 80 | J5: 4.7 | K5: 2023 | L5: Wednesday | M5: 1 to 2 hours | N5: 5 | O5: 307
A6: Call_7313 | B6: C0009 | C6: Female | D6: 25 | E6: Columbus | F6: 89 | G6: R05 | H6: 44944 | I6: 155 | J6: 4.1 | K6: 2023 | L6: Wednesday | M6: 1 to 2 hours | N6: 4 | O6: 307
A7: Call_7314 | B7: C0013 | C7: Female | D7: 37 | E7: Cleveland | F7: 132 | G7: R03 | H7: 44944 | I7: 168 | J7: 4.1 | K7: 2023 | L7: Wednesday | M7: More than 2 hours | N7: 4 | O7: 307
A8: Call_7315 | B8: C0001 | C8: Male | D8: 41 | E8: Columbus | F8: 105 | G8: R01 | H8: 44944 | I8: 56 | J8: 3.6 | K8: 2023 | L8: Wednesday | M8: 1 to 2 hours | N8: 4 | O8: 307
A9: Call_7334 | B9: C0013 | C9: Female | D9: 37 | E9: Cleveland | F9: 71 | G9: R05 | H9: 44951 | I9: 90 | J9: 3.8 | K9: 2023 | L9: Wednesday | M9: 1 to 2 hours | N9: 4 | O9: 307
A10: Call_7335 | B10: C0001 | C10: Male | D10: 41 | E10: Columbus | F10: 147 | G10: R04 | H10: 44951 | I10: 105 | J10: 4.4 | K10: 2023 | L10: Wednesday | M10: More than 2 hours | N10: 4 | O10: 307
A11: Call_7350 | B11: C0009 | C11: Female | D11: 25 | E11: Columbus | F11: 79 | G11: R03 | H11: 44958 | I11: 148 | J11: 4.5 | K11: 2023 | L11: Wednesday | M11: 1 to 2 hours | N11: 5 | O11: 307
A12: Call_7351 | B12: C0010 | C12: Female | D12: 30 | E12: Cleveland | F12: 45 | G12: R04 | H12: 44958 | I12: 34 | J12: 3.7 | K12: 2023 | L12: Wednesday | M12: 30 to 60 mins | N12: 4 | O12: 307
A13: Call_7352 | B13: C0011 | C13: Female | D13: 30 | E13: Cincinnati | F13: 137 | G13: R03 | H13: 44958 | I13: 86 | J13: 4.8 | K13: 2023 | L13: Wednesday | M13: More than 2 hours | N13: 5 | O13: 307
... A154: Call_8258 | B154: C0009 | C154: Female | D154: 25 | E154: Columbus | F154: 72 | G154: R05 | H154: 45287 | I154: 164 | J154: 4.8 | K154: 2024 | L154: Wednesday | M154: 1 to 2 hours | N154: 5 | O154: 307

Sheet Customer Centre Data
G37: =Sheet3!A5 -> 1000 | K37: =Sheet3!C5 -> 96623 | O37: =Sheet3!B5 -> 89850 | S37: =Sheet3!E5 -> 3.8854 | W37: =Sheet3!D5 -> 307
G39: =Sheet3!A15 -> 200 | K39: =Sheet3!C15 -> 20104 | O39: =Sheet3!B15 -> 18209 | S39: =Sheet3!E15 -> 3.8825 | W39: =Sheet3!D15 -> 307
U61: {=Sheet3!D144:H144} -> R01 | V61: R02 | W61: R03 | X61: R04 | Y61: R05 | Z61: Total
S62: Cincinnati
T63: C0003 | U63: 891 | V63: 1332 | W63: 1282 | X63: 739 | Y63: 560 | Z63: 4804
T64: C0004 | U64: 1991 | V64: 1886 | W64: 1206 | X64: 884 | Y64: 1722 | Z64: 7689
T65: C0011 | U65: 1163 | V65: 1180 | W65: 1616 | X65: 1043 | Y65: 1747 | Z65: 6749
T66: C0012 | U66: 1438 | V66: 1616 | W66: 866 | X66: 829 | Y66: 2070 | Z66: 6819
S67: Cleveland
T68: C0002 | U68: 1233 | V68: 223 | W68: 1680 | X68: 990 | Y68: 1508 | Z68: 5634
T69: C0007 | U69: 1598 | V69: 1907 | W69: 869 | X69: 1426 | Y69: 1416 | Z69: 7216
T70: C0008 | U70: 900 | V70: 1016 | W70: 960 | X70: 940 | Y70: 1193 | Z70: 5009
T71: C0010 | U71: 900 | V71: 1470 | W71: 1617 | X71: 1314 | Y71: 941 | Z71: 6242
T72: C0013 | U72: 1255 | V72: 516 | W72: 1874 | X72: 1863 | Y72: 1722 | Z72: 7230
T73: C0015 | U73: 1138 | V73: 1898 | W73: 1482 | X73: 846 | Y73: 1154 | Z73: 6518
S74: Columbus
P75: =Sheet3!N116 -> =DISPIMG("ID_EC911822DCF444EC8A14DF6B7BA76BC9",1) | T75: C0001 | U75: 1655 | V75: 805 | W75: 2263 | X75: 987 | Y75: 1075 | Z75: 6785
T76: C0005 | U76: 1104 | V76: 2280 | W76: 1445 | X76: 1722 | Y76: 1196 | Z76: 7747
T77: C0006 | U77: 372 | V77: 1818 | W77: 1346 | X77: 1156 | Y77: 1484 | Z77: 6176
T78: C0009 | U78: 1415 | V78: 1271 | W78: 1214 | X78: 1135 | Y78: 1566 | Z78: 6601
T79: C0014 | U79: 1362 | V79: 1363 | W79: 1152 | X79: 777 | Y79: 750 | Z79: 5404
P80: =Sheet3!N110 -> % of calls:20%
P81: =Sheet3!N111 -> Call rank:3
P82: =Sheet3!N112 -> Amount rank:3
